<?xml version="1.0" ?>

<robot name="cartographer_backpack_3d">

  <link name="camera"/>
  <link name="imu"/>
  <link name="head_lidar_mount_link"/>
  <link name="laser"/>
  
  <joint name="head/main" type="fixed">
    <origin xyz="0.04 -0.03 0" rpy="0 -1.5708 -1.5708"/>
    <parent link="camera"/>
    <child link="imu"/>
  </joint>

  <joint name="head_lidar_spinning_joint" type="continuous">
    <parent link="camera" />
    <child link="head_lidar_mount_link"/>
    <origin xyz="0 0 0" rpy="0 0 0" />
    <axis xyz="0 0 1" rpy="0 0 0"/>
  </joint>

  <joint name="head/head_hokuyo_frame_joint" type="fixed">
    <origin xyz="0 0.055 0.0" rpy="-1.5708 -1.5708 0" />
    <parent link="head_lidar_mount_link" />
    <child link="laser"/>
  </joint>

</robot>

